[2024-07-23T19:51:29.747+0000] {local_task_job_runner.py:120} INFO - ::group::Pre task execution logs
[2024-07-23T19:51:29.855+0000] {taskinstance.py:2076} INFO - Dependencies all met for dep_context=non-requeueable deps ti=<TaskInstance: processar_dados_brewery.transformar_dados_para_silver manual__2024-07-23T19:46:16.266878+00:00 [queued]>
[2024-07-23T19:51:29.861+0000] {taskinstance.py:2076} INFO - Dependencies all met for dep_context=requeueable deps ti=<TaskInstance: processar_dados_brewery.transformar_dados_para_silver manual__2024-07-23T19:46:16.266878+00:00 [queued]>
[2024-07-23T19:51:29.862+0000] {taskinstance.py:2306} INFO - Starting attempt 2 of 2
[2024-07-23T19:51:29.876+0000] {taskinstance.py:2330} INFO - Executing <Task(PythonOperator): transformar_dados_para_silver> on 2024-07-23 19:46:16.266878+00:00
[2024-07-23T19:51:29.880+0000] {warnings.py:112} WARNING - /home/***/.local/lib/python3.12/site-packages/***/task/task_runner/standard_task_runner.py:62: DeprecationWarning: This process (pid=151) is multi-threaded, use of fork() may lead to deadlocks in the child.
  pid = os.fork()

[2024-07-23T19:51:29.881+0000] {standard_task_runner.py:64} INFO - Started process 153 to run task
[2024-07-23T19:51:29.880+0000] {standard_task_runner.py:90} INFO - Running: ['***', 'tasks', 'run', 'processar_dados_brewery', 'transformar_dados_para_silver', 'manual__2024-07-23T19:46:16.266878+00:00', '--job-id', '48', '--raw', '--subdir', 'DAGS_FOLDER/rotina_principal.py', '--cfg-path', '/tmp/tmp0e46916c']
[2024-07-23T19:51:29.882+0000] {standard_task_runner.py:91} INFO - Job 48: Subtask transformar_dados_para_silver
[2024-07-23T19:51:29.912+0000] {task_command.py:426} INFO - Running <TaskInstance: processar_dados_brewery.transformar_dados_para_silver manual__2024-07-23T19:46:16.266878+00:00 [running]> on host 84773d6c55d8
[2024-07-23T19:51:29.966+0000] {taskinstance.py:2648} INFO - Exporting env vars: AIRFLOW_CTX_DAG_OWNER='***' AIRFLOW_CTX_DAG_ID='processar_dados_brewery' AIRFLOW_CTX_TASK_ID='transformar_dados_para_silver' AIRFLOW_CTX_EXECUTION_DATE='2024-07-23T19:46:16.266878+00:00' AIRFLOW_CTX_TRY_NUMBER='2' AIRFLOW_CTX_DAG_RUN_ID='manual__2024-07-23T19:46:16.266878+00:00'
[2024-07-23T19:51:29.967+0000] {taskinstance.py:430} INFO - ::endgroup::
[2024-07-23T19:51:31.924+0000] {taskinstance.py:441} INFO - ::group::Post task execution logs
[2024-07-23T19:51:31.928+0000] {taskinstance.py:2905} ERROR - Task failed with exception
Traceback (most recent call last):
  File "/home/airflow/.local/lib/python3.12/site-packages/airflow/models/taskinstance.py", line 465, in _execute_task
    result = _execute_callable(context=context, **execute_callable_kwargs)
             ^^^^^^^^^^^^^^^^^^^^^^^^^^^^^^^^^^^^^^^^^^^^^^^^^^^^^^^^^^^^^
  File "/home/airflow/.local/lib/python3.12/site-packages/airflow/models/taskinstance.py", line 432, in _execute_callable
    return execute_callable(context=context, **execute_callable_kwargs)
           ^^^^^^^^^^^^^^^^^^^^^^^^^^^^^^^^^^^^^^^^^^^^^^^^^^^^^^^^^^^^
  File "/home/airflow/.local/lib/python3.12/site-packages/airflow/models/baseoperator.py", line 401, in wrapper
    return func(self, *args, **kwargs)
           ^^^^^^^^^^^^^^^^^^^^^^^^^^^
  File "/home/airflow/.local/lib/python3.12/site-packages/airflow/operators/python.py", line 235, in execute
    return_value = self.execute_callable()
                   ^^^^^^^^^^^^^^^^^^^^^^^
  File "/home/airflow/.local/lib/python3.12/site-packages/airflow/operators/python.py", line 252, in execute_callable
    return self.python_callable(*self.op_args, **self.op_kwargs)
           ^^^^^^^^^^^^^^^^^^^^^^^^^^^^^^^^^^^^^^^^^^^^^^^^^^^^^
  File "/opt/airflow/dags/datalake_functions.py", line 139, in transformar_dados_para_silver
    df.to_parquet(silver_parquet_path, index=False, partition_cols=["estado", "cidade"])
  File "/home/airflow/.local/lib/python3.12/site-packages/pandas/core/frame.py", line 2970, in to_parquet
    return to_parquet(
           ^^^^^^^^^^^
  File "/home/airflow/.local/lib/python3.12/site-packages/pandas/io/parquet.py", line 483, in to_parquet
    impl.write(
  File "/home/airflow/.local/lib/python3.12/site-packages/pandas/io/parquet.py", line 216, in write
    self.api.parquet.write_to_dataset(
  File "/home/airflow/.local/lib/python3.12/site-packages/pyarrow/parquet/core.py", line 2138, in write_to_dataset
    ds.write_dataset(
  File "/home/airflow/.local/lib/python3.12/site-packages/pyarrow/dataset.py", line 1030, in write_dataset
    _filesystemdataset_write(
  File "pyarrow/_dataset.pyx", line 4010, in pyarrow._dataset._filesystemdataset_write
  File "pyarrow/error.pxi", line 91, in pyarrow.lib.check_status
pyarrow.lib.ArrowInvalid: Fragment would be written into 3663 partitions. This exceeds the maximum of 1024
[2024-07-23T19:51:31.939+0000] {taskinstance.py:1206} INFO - Marking task as FAILED. dag_id=processar_dados_brewery, task_id=transformar_dados_para_silver, run_id=manual__2024-07-23T19:46:16.266878+00:00, execution_date=20240723T194616, start_date=20240723T195129, end_date=20240723T195131
[2024-07-23T19:51:31.940+0000] {warnings.py:112} WARNING - /home/***/.local/lib/python3.12/site-packages/***/utils/context.py:212: AirflowContextDeprecationWarning: Accessing 'execution_date' from the template is deprecated and will be removed in a future version. Please use 'data_interval_start' or 'logical_date' instead.
  warnings.warn(_create_deprecation_warning(key, self._deprecation_replacements[key]))

[2024-07-23T19:51:31.946+0000] {warnings.py:112} WARNING - /home/***/.local/lib/python3.12/site-packages/***/utils/email.py:154: RemovedInAirflow3Warning: Fetching SMTP credentials from configuration variables will be deprecated in a future release. Please set credentials using a connection instead.
  send_mime_email(e_from=mail_from, e_to=recipients, mime_msg=msg, conn_id=conn_id, dryrun=dryrun)

[2024-07-23T19:51:31.946+0000] {configuration.py:1053} WARNING - section/key [smtp/smtp_user] not found in config
[2024-07-23T19:51:31.946+0000] {email.py:271} INFO - Email alerting: attempt 1
[2024-07-23T19:51:31.947+0000] {taskinstance.py:1182} ERROR - Error when executing enviar_email_falha callback
Traceback (most recent call last):
  File "/home/airflow/.local/lib/python3.12/site-packages/airflow/models/taskinstance.py", line 2479, in _run_raw_task
    self._execute_task_with_callbacks(context, test_mode, session=session)
  File "/home/airflow/.local/lib/python3.12/site-packages/airflow/models/taskinstance.py", line 2676, in _execute_task_with_callbacks
    result = self._execute_task(context, task_orig)
             ^^^^^^^^^^^^^^^^^^^^^^^^^^^^^^^^^^^^^^
  File "/home/airflow/.local/lib/python3.12/site-packages/airflow/models/taskinstance.py", line 2701, in _execute_task
    return _execute_task(self, context, task_orig)
           ^^^^^^^^^^^^^^^^^^^^^^^^^^^^^^^^^^^^^^^
  File "/home/airflow/.local/lib/python3.12/site-packages/airflow/models/taskinstance.py", line 465, in _execute_task
    result = _execute_callable(context=context, **execute_callable_kwargs)
             ^^^^^^^^^^^^^^^^^^^^^^^^^^^^^^^^^^^^^^^^^^^^^^^^^^^^^^^^^^^^^
  File "/home/airflow/.local/lib/python3.12/site-packages/airflow/models/taskinstance.py", line 432, in _execute_callable
    return execute_callable(context=context, **execute_callable_kwargs)
           ^^^^^^^^^^^^^^^^^^^^^^^^^^^^^^^^^^^^^^^^^^^^^^^^^^^^^^^^^^^^
  File "/home/airflow/.local/lib/python3.12/site-packages/airflow/models/baseoperator.py", line 401, in wrapper
    return func(self, *args, **kwargs)
           ^^^^^^^^^^^^^^^^^^^^^^^^^^^
  File "/home/airflow/.local/lib/python3.12/site-packages/airflow/operators/python.py", line 235, in execute
    return_value = self.execute_callable()
                   ^^^^^^^^^^^^^^^^^^^^^^^
  File "/home/airflow/.local/lib/python3.12/site-packages/airflow/operators/python.py", line 252, in execute_callable
    return self.python_callable(*self.op_args, **self.op_kwargs)
           ^^^^^^^^^^^^^^^^^^^^^^^^^^^^^^^^^^^^^^^^^^^^^^^^^^^^^
  File "/opt/airflow/dags/datalake_functions.py", line 139, in transformar_dados_para_silver
    df.to_parquet(silver_parquet_path, index=False, partition_cols=["estado", "cidade"])
  File "/home/airflow/.local/lib/python3.12/site-packages/pandas/core/frame.py", line 2970, in to_parquet
    return to_parquet(
           ^^^^^^^^^^^
  File "/home/airflow/.local/lib/python3.12/site-packages/pandas/io/parquet.py", line 483, in to_parquet
    impl.write(
  File "/home/airflow/.local/lib/python3.12/site-packages/pandas/io/parquet.py", line 216, in write
    self.api.parquet.write_to_dataset(
  File "/home/airflow/.local/lib/python3.12/site-packages/pyarrow/parquet/core.py", line 2138, in write_to_dataset
    ds.write_dataset(
  File "/home/airflow/.local/lib/python3.12/site-packages/pyarrow/dataset.py", line 1030, in write_dataset
    _filesystemdataset_write(
  File "pyarrow/_dataset.pyx", line 4010, in pyarrow._dataset._filesystemdataset_write
  File "pyarrow/error.pxi", line 91, in pyarrow.lib.check_status
pyarrow.lib.ArrowInvalid: Fragment would be written into 3663 partitions. This exceeds the maximum of 1024

During handling of the above exception, another exception occurred:

Traceback (most recent call last):
  File "/home/airflow/.local/lib/python3.12/site-packages/airflow/models/taskinstance.py", line 1179, in _run_finished_callback
    callback(context)
  File "/opt/airflow/dags/rotina_principal.py", line 19, in enviar_email_falha
    send_email(email_to, subject, html_content)
  File "/home/airflow/.local/lib/python3.12/site-packages/airflow/utils/email.py", line 80, in send_email
    return backend(
           ^^^^^^^^
  File "/home/airflow/.local/lib/python3.12/site-packages/airflow/utils/email.py", line 154, in send_email_smtp
    send_mime_email(e_from=mail_from, e_to=recipients, mime_msg=msg, conn_id=conn_id, dryrun=dryrun)
  File "/home/airflow/.local/lib/python3.12/site-packages/airflow/utils/email.py", line 273, in send_mime_email
    smtp_conn = _get_smtp_connection(smtp_host, smtp_port, smtp_timeout, smtp_ssl)
                ^^^^^^^^^^^^^^^^^^^^^^^^^^^^^^^^^^^^^^^^^^^^^^^^^^^^^^^^^^^^^^^^^^
  File "/home/airflow/.local/lib/python3.12/site-packages/airflow/utils/email.py", line 317, in _get_smtp_connection
    return smtplib.SMTP(host=host, port=port, timeout=timeout)
           ^^^^^^^^^^^^^^^^^^^^^^^^^^^^^^^^^^^^^^^^^^^^^^^^^^^
  File "/usr/local/lib/python3.12/smtplib.py", line 255, in __init__
    (code, msg) = self.connect(host, port)
                  ^^^^^^^^^^^^^^^^^^^^^^^^
  File "/usr/local/lib/python3.12/smtplib.py", line 341, in connect
    self.sock = self._get_socket(host, port, self.timeout)
                ^^^^^^^^^^^^^^^^^^^^^^^^^^^^^^^^^^^^^^^^^^
  File "/usr/local/lib/python3.12/smtplib.py", line 312, in _get_socket
    return socket.create_connection((host, port), timeout,
           ^^^^^^^^^^^^^^^^^^^^^^^^^^^^^^^^^^^^^^^^^^^^^^^
  File "/usr/local/lib/python3.12/socket.py", line 853, in create_connection
    raise exceptions[0]
  File "/usr/local/lib/python3.12/socket.py", line 838, in create_connection
    sock.connect(sa)
ConnectionRefusedError: [Errno 111] Connection refused
[2024-07-23T19:51:31.958+0000] {standard_task_runner.py:110} ERROR - Failed to execute job 48 for task transformar_dados_para_silver (Fragment would be written into 3663 partitions. This exceeds the maximum of 1024; 153)
[2024-07-23T19:51:31.979+0000] {local_task_job_runner.py:243} INFO - Task exited with return code 1
[2024-07-23T19:51:31.993+0000] {taskinstance.py:3503} INFO - 0 downstream tasks scheduled from follow-on schedule check
[2024-07-23T19:51:31.996+0000] {local_task_job_runner.py:222} INFO - ::endgroup::
