[2024-07-23T19:38:41.830+0000] {local_task_job_runner.py:120} INFO - ::group::Pre task execution logs
[2024-07-23T19:38:41.952+0000] {taskinstance.py:2076} INFO - Dependencies all met for dep_context=non-requeueable deps ti=<TaskInstance: processar_dados_brewery.buscar_e_salvar_dados_brewery scheduled__2024-07-22T00:00:00+00:00 [queued]>
[2024-07-23T19:38:41.957+0000] {taskinstance.py:2076} INFO - Dependencies all met for dep_context=requeueable deps ti=<TaskInstance: processar_dados_brewery.buscar_e_salvar_dados_brewery scheduled__2024-07-22T00:00:00+00:00 [queued]>
[2024-07-23T19:38:41.958+0000] {taskinstance.py:2306} INFO - Starting attempt 2 of 2
[2024-07-23T19:38:41.967+0000] {taskinstance.py:2330} INFO - Executing <Task(PythonOperator): buscar_e_salvar_dados_brewery> on 2024-07-22 00:00:00+00:00
[2024-07-23T19:38:41.971+0000] {warnings.py:112} WARNING - /home/***/.local/lib/python3.12/site-packages/***/task/task_runner/standard_task_runner.py:62: DeprecationWarning: This process (pid=140) is multi-threaded, use of fork() may lead to deadlocks in the child.
  pid = os.fork()

[2024-07-23T19:38:41.972+0000] {standard_task_runner.py:64} INFO - Started process 142 to run task
[2024-07-23T19:38:41.972+0000] {standard_task_runner.py:90} INFO - Running: ['***', 'tasks', 'run', 'processar_dados_brewery', 'buscar_e_salvar_dados_brewery', 'scheduled__2024-07-22T00:00:00+00:00', '--job-id', '41', '--raw', '--subdir', 'DAGS_FOLDER/rotina_principal.py', '--cfg-path', '/tmp/tmp4iuu06ou']
[2024-07-23T19:38:41.974+0000] {standard_task_runner.py:91} INFO - Job 41: Subtask buscar_e_salvar_dados_brewery
[2024-07-23T19:38:42.004+0000] {task_command.py:426} INFO - Running <TaskInstance: processar_dados_brewery.buscar_e_salvar_dados_brewery scheduled__2024-07-22T00:00:00+00:00 [running]> on host 4400ed802372
[2024-07-23T19:38:42.058+0000] {taskinstance.py:2648} INFO - Exporting env vars: AIRFLOW_CTX_DAG_OWNER='***' AIRFLOW_CTX_DAG_ID='processar_dados_brewery' AIRFLOW_CTX_TASK_ID='buscar_e_salvar_dados_brewery' AIRFLOW_CTX_EXECUTION_DATE='2024-07-22T00:00:00+00:00' AIRFLOW_CTX_TRY_NUMBER='2' AIRFLOW_CTX_DAG_RUN_ID='scheduled__2024-07-22T00:00:00+00:00'
[2024-07-23T19:38:42.058+0000] {taskinstance.py:430} INFO - ::endgroup::
[2024-07-23T19:38:42.073+0000] {taskinstance.py:441} INFO - ::group::Post task execution logs
[2024-07-23T19:38:42.074+0000] {taskinstance.py:2905} ERROR - Task failed with exception
Traceback (most recent call last):
  File "/home/airflow/.local/lib/python3.12/site-packages/airflow/models/taskinstance.py", line 465, in _execute_task
    result = _execute_callable(context=context, **execute_callable_kwargs)
             ^^^^^^^^^^^^^^^^^^^^^^^^^^^^^^^^^^^^^^^^^^^^^^^^^^^^^^^^^^^^^
  File "/home/airflow/.local/lib/python3.12/site-packages/airflow/models/taskinstance.py", line 432, in _execute_callable
    return execute_callable(context=context, **execute_callable_kwargs)
           ^^^^^^^^^^^^^^^^^^^^^^^^^^^^^^^^^^^^^^^^^^^^^^^^^^^^^^^^^^^^
  File "/home/airflow/.local/lib/python3.12/site-packages/airflow/models/baseoperator.py", line 401, in wrapper
    return func(self, *args, **kwargs)
           ^^^^^^^^^^^^^^^^^^^^^^^^^^^
  File "/home/airflow/.local/lib/python3.12/site-packages/airflow/operators/python.py", line 235, in execute
    return_value = self.execute_callable()
                   ^^^^^^^^^^^^^^^^^^^^^^^
  File "/home/airflow/.local/lib/python3.12/site-packages/airflow/operators/python.py", line 252, in execute_callable
    return self.python_callable(*self.op_args, **self.op_kwargs)
           ^^^^^^^^^^^^^^^^^^^^^^^^^^^^^^^^^^^^^^^^^^^^^^^^^^^^^
  File "/opt/airflow/dags/datalake_functions.py", line 11, in buscar_e_salvar_dados_brewery
    os.makedirs(landing_zone_path, exist_ok=True)
  File "<frozen os>", line 225, in makedirs
FileNotFoundError: [Errno 2] No such file or directory: '/opt/airflow/datalake/landing_zone'
[2024-07-23T19:38:42.081+0000] {taskinstance.py:1206} INFO - Marking task as FAILED. dag_id=processar_dados_brewery, task_id=buscar_e_salvar_dados_brewery, run_id=scheduled__2024-07-22T00:00:00+00:00, execution_date=20240722T000000, start_date=20240723T193841, end_date=20240723T193842
[2024-07-23T19:38:42.083+0000] {taskinstance.py:1182} ERROR - Error when executing enviar_email_falha callback
Traceback (most recent call last):
  File "/home/airflow/.local/lib/python3.12/site-packages/airflow/models/taskinstance.py", line 2479, in _run_raw_task
    self._execute_task_with_callbacks(context, test_mode, session=session)
  File "/home/airflow/.local/lib/python3.12/site-packages/airflow/models/taskinstance.py", line 2676, in _execute_task_with_callbacks
    result = self._execute_task(context, task_orig)
             ^^^^^^^^^^^^^^^^^^^^^^^^^^^^^^^^^^^^^^
  File "/home/airflow/.local/lib/python3.12/site-packages/airflow/models/taskinstance.py", line 2701, in _execute_task
    return _execute_task(self, context, task_orig)
           ^^^^^^^^^^^^^^^^^^^^^^^^^^^^^^^^^^^^^^^
  File "/home/airflow/.local/lib/python3.12/site-packages/airflow/models/taskinstance.py", line 465, in _execute_task
    result = _execute_callable(context=context, **execute_callable_kwargs)
             ^^^^^^^^^^^^^^^^^^^^^^^^^^^^^^^^^^^^^^^^^^^^^^^^^^^^^^^^^^^^^
  File "/home/airflow/.local/lib/python3.12/site-packages/airflow/models/taskinstance.py", line 432, in _execute_callable
    return execute_callable(context=context, **execute_callable_kwargs)
           ^^^^^^^^^^^^^^^^^^^^^^^^^^^^^^^^^^^^^^^^^^^^^^^^^^^^^^^^^^^^
  File "/home/airflow/.local/lib/python3.12/site-packages/airflow/models/baseoperator.py", line 401, in wrapper
    return func(self, *args, **kwargs)
           ^^^^^^^^^^^^^^^^^^^^^^^^^^^
  File "/home/airflow/.local/lib/python3.12/site-packages/airflow/operators/python.py", line 235, in execute
    return_value = self.execute_callable()
                   ^^^^^^^^^^^^^^^^^^^^^^^
  File "/home/airflow/.local/lib/python3.12/site-packages/airflow/operators/python.py", line 252, in execute_callable
    return self.python_callable(*self.op_args, **self.op_kwargs)
           ^^^^^^^^^^^^^^^^^^^^^^^^^^^^^^^^^^^^^^^^^^^^^^^^^^^^^
  File "/opt/airflow/dags/datalake_functions.py", line 11, in buscar_e_salvar_dados_brewery
    os.makedirs(landing_zone_path, exist_ok=True)
  File "<frozen os>", line 225, in makedirs
FileNotFoundError: [Errno 2] No such file or directory: '/opt/airflow/datalake/landing_zone'

During handling of the above exception, another exception occurred:

Traceback (most recent call last):
  File "/home/airflow/.local/lib/python3.12/site-packages/airflow/models/taskinstance.py", line 1179, in _run_finished_callback
    callback(context)
  File "/opt/airflow/dags/rotina_principal.py", line 11, in enviar_email_falha
    email_to = Variable.get("email_failure")
               ^^^^^^^^^^^^^^^^^^^^^^^^^^^^^
  File "/home/airflow/.local/lib/python3.12/site-packages/airflow/models/variable.py", line 143, in get
    raise KeyError(f"Variable {key} does not exist")
KeyError: 'Variable email_failure does not exist'
[2024-07-23T19:38:42.095+0000] {standard_task_runner.py:110} ERROR - Failed to execute job 41 for task buscar_e_salvar_dados_brewery ([Errno 2] No such file or directory: '/opt/airflow/datalake/landing_zone'; 142)
[2024-07-23T19:38:42.105+0000] {local_task_job_runner.py:243} INFO - Task exited with return code 1
[2024-07-23T19:38:42.120+0000] {taskinstance.py:3503} INFO - 0 downstream tasks scheduled from follow-on schedule check
[2024-07-23T19:38:42.124+0000] {local_task_job_runner.py:222} INFO - ::endgroup::
