[2024-07-21T21:25:09.814+0000] {local_task_job_runner.py:120} INFO - ::group::Pre task execution logs
[2024-07-21T21:25:09.830+0000] {taskinstance.py:2076} INFO - Dependencies all met for dep_context=non-requeueable deps ti=<TaskInstance: execute_databricks_workflow.run_databricks_workflow scheduled__2024-07-20T00:00:00+00:00 [queued]>
[2024-07-21T21:25:09.836+0000] {taskinstance.py:2076} INFO - Dependencies all met for dep_context=requeueable deps ti=<TaskInstance: execute_databricks_workflow.run_databricks_workflow scheduled__2024-07-20T00:00:00+00:00 [queued]>
[2024-07-21T21:25:09.836+0000] {taskinstance.py:2306} INFO - Starting attempt 1 of 2
[2024-07-21T21:25:09.845+0000] {taskinstance.py:2330} INFO - Executing <Task(PythonOperator): run_databricks_workflow> on 2024-07-20 00:00:00+00:00
[2024-07-21T21:25:09.849+0000] {warnings.py:112} WARNING - /home/***/.local/lib/python3.12/site-packages/***/task/task_runner/standard_task_runner.py:62: DeprecationWarning: This process (pid=105) is multi-threaded, use of fork() may lead to deadlocks in the child.
  pid = os.fork()

[2024-07-21T21:25:09.850+0000] {standard_task_runner.py:64} INFO - Started process 107 to run task
[2024-07-21T21:25:09.850+0000] {standard_task_runner.py:90} INFO - Running: ['***', 'tasks', 'run', 'execute_databricks_workflow', 'run_databricks_workflow', 'scheduled__2024-07-20T00:00:00+00:00', '--job-id', '13', '--raw', '--subdir', 'DAGS_FOLDER/rotina_principal.py', '--cfg-path', '/tmp/tmpq63h_51r']
[2024-07-21T21:25:09.851+0000] {standard_task_runner.py:91} INFO - Job 13: Subtask run_databricks_workflow
[2024-07-21T21:25:09.881+0000] {task_command.py:426} INFO - Running <TaskInstance: execute_databricks_workflow.run_databricks_workflow scheduled__2024-07-20T00:00:00+00:00 [running]> on host 383843094d1c
[2024-07-21T21:25:09.930+0000] {taskinstance.py:2648} INFO - Exporting env vars: AIRFLOW_CTX_DAG_OWNER='***' AIRFLOW_CTX_DAG_ID='execute_databricks_workflow' AIRFLOW_CTX_TASK_ID='run_databricks_workflow' AIRFLOW_CTX_EXECUTION_DATE='2024-07-20T00:00:00+00:00' AIRFLOW_CTX_TRY_NUMBER='1' AIRFLOW_CTX_DAG_RUN_ID='scheduled__2024-07-20T00:00:00+00:00'
[2024-07-21T21:25:09.931+0000] {taskinstance.py:430} INFO - ::endgroup::
[2024-07-21T21:25:09.946+0000] {taskinstance.py:441} INFO - ::group::Post task execution logs
[2024-07-21T21:25:09.947+0000] {taskinstance.py:2905} ERROR - Task failed with exception
Traceback (most recent call last):
  File "/home/airflow/.local/lib/python3.12/site-packages/airflow/models/taskinstance.py", line 465, in _execute_task
    result = _execute_callable(context=context, **execute_callable_kwargs)
             ^^^^^^^^^^^^^^^^^^^^^^^^^^^^^^^^^^^^^^^^^^^^^^^^^^^^^^^^^^^^^
  File "/home/airflow/.local/lib/python3.12/site-packages/airflow/models/taskinstance.py", line 432, in _execute_callable
    return execute_callable(context=context, **execute_callable_kwargs)
           ^^^^^^^^^^^^^^^^^^^^^^^^^^^^^^^^^^^^^^^^^^^^^^^^^^^^^^^^^^^^
  File "/home/airflow/.local/lib/python3.12/site-packages/airflow/models/baseoperator.py", line 401, in wrapper
    return func(self, *args, **kwargs)
           ^^^^^^^^^^^^^^^^^^^^^^^^^^^
  File "/home/airflow/.local/lib/python3.12/site-packages/airflow/operators/python.py", line 235, in execute
    return_value = self.execute_callable()
                   ^^^^^^^^^^^^^^^^^^^^^^^
  File "/home/airflow/.local/lib/python3.12/site-packages/airflow/operators/python.py", line 252, in execute_callable
    return self.python_callable(*self.op_args, **self.op_kwargs)
           ^^^^^^^^^^^^^^^^^^^^^^^^^^^^^^^^^^^^^^^^^^^^^^^^^^^^^
  File "/opt/airflow/dags/rotina_principal.py", line 79, in run_databricks_job
    databricks_instance = Variable.get("databricks_instance")
                          ^^^^^^^^^^^^^^^^^^^^^^^^^^^^^^^^^^^
  File "/home/airflow/.local/lib/python3.12/site-packages/airflow/models/variable.py", line 143, in get
    raise KeyError(f"Variable {key} does not exist")
KeyError: 'Variable databricks_instance does not exist'
[2024-07-21T21:25:09.956+0000] {taskinstance.py:1206} INFO - Marking task as UP_FOR_RETRY. dag_id=execute_databricks_workflow, task_id=run_databricks_workflow, run_id=scheduled__2024-07-20T00:00:00+00:00, execution_date=20240720T000000, start_date=20240721T212509, end_date=20240721T212509
[2024-07-21T21:25:09.965+0000] {standard_task_runner.py:110} ERROR - Failed to execute job 13 for task run_databricks_workflow ('Variable databricks_instance does not exist'; 107)
[2024-07-21T21:25:09.983+0000] {local_task_job_runner.py:243} INFO - Task exited with return code 1
[2024-07-21T21:25:09.996+0000] {taskinstance.py:3503} INFO - 0 downstream tasks scheduled from follow-on schedule check
[2024-07-21T21:25:09.998+0000] {local_task_job_runner.py:222} INFO - ::endgroup::
